Traceback (most recent call last):
  File "/opt/hostedtoolcache/Python/3.8.18/x64/lib/python3.8/site-packages/jupyter_cache/executors/utils.py", line 58, in single_nb_execution
    executenb(
  File "/opt/hostedtoolcache/Python/3.8.18/x64/lib/python3.8/site-packages/nbclient/client.py", line 1305, in execute
    return NotebookClient(nb=nb, resources=resources, km=km, **kwargs).execute()
  File "/opt/hostedtoolcache/Python/3.8.18/x64/lib/python3.8/site-packages/jupyter_core/utils/__init__.py", line 168, in wrapped
    return loop.run_until_complete(inner)
  File "/opt/hostedtoolcache/Python/3.8.18/x64/lib/python3.8/asyncio/base_events.py", line 616, in run_until_complete
    return future.result()
  File "/opt/hostedtoolcache/Python/3.8.18/x64/lib/python3.8/site-packages/nbclient/client.py", line 705, in async_execute
    await self.async_execute_cell(
  File "/opt/hostedtoolcache/Python/3.8.18/x64/lib/python3.8/site-packages/nbclient/client.py", line 1058, in async_execute_cell
    await self._check_raise_for_error(cell, cell_index, exec_reply)
  File "/opt/hostedtoolcache/Python/3.8.18/x64/lib/python3.8/site-packages/nbclient/client.py", line 914, in _check_raise_for_error
    raise CellExecutionError.from_cell_and_msg(cell, exec_reply_content)
nbclient.exceptions.CellExecutionError: An error occurred while executing the following cell:
------------------
import os
path = '/home/wsuser/work/quantum-fed-infer'

#作業ディレクトリをpathに移動する
os.chdir(path)

#作業ディレクトリ直下のファイルを確認
!ls
------------------


[0;31m---------------------------------------------------------------------------[0m
[0;31mFileNotFoundError[0m                         Traceback (most recent call last)
Cell [0;32mIn[4], line 5[0m
[1;32m      2[0m path [38;5;241m=[39m [38;5;124m'[39m[38;5;124m/home/wsuser/work/quantum-fed-infer[39m[38;5;124m'[39m
[1;32m      4[0m [38;5;66;03m#作業ディレクトリをpathに移動する[39;00m
[0;32m----> 5[0m [43mos[49m[38;5;241;43m.[39;49m[43mchdir[49m[43m([49m[43mpath[49m[43m)[49m
[1;32m      7[0m [38;5;66;03m#作業ディレクトリ直下のファイルを確認[39;00m
[1;32m      8[0m get_ipython()[38;5;241m.[39msystem([38;5;124m'[39m[38;5;124mls[39m[38;5;124m'[39m)

[0;31mFileNotFoundError[0m: [Errno 2] No such file or directory: '/home/wsuser/work/quantum-fed-infer'

