Traceback (most recent call last):
  File "/opt/hostedtoolcache/Python/3.8.18/x64/lib/python3.8/site-packages/jupyter_cache/executors/utils.py", line 58, in single_nb_execution
    executenb(
  File "/opt/hostedtoolcache/Python/3.8.18/x64/lib/python3.8/site-packages/nbclient/client.py", line 1305, in execute
    return NotebookClient(nb=nb, resources=resources, km=km, **kwargs).execute()
  File "/opt/hostedtoolcache/Python/3.8.18/x64/lib/python3.8/site-packages/jupyter_core/utils/__init__.py", line 168, in wrapped
    return loop.run_until_complete(inner)
  File "/opt/hostedtoolcache/Python/3.8.18/x64/lib/python3.8/asyncio/base_events.py", line 616, in run_until_complete
    return future.result()
  File "/opt/hostedtoolcache/Python/3.8.18/x64/lib/python3.8/site-packages/nbclient/client.py", line 705, in async_execute
    await self.async_execute_cell(
  File "/opt/hostedtoolcache/Python/3.8.18/x64/lib/python3.8/site-packages/nbclient/client.py", line 1058, in async_execute_cell
    await self._check_raise_for_error(cell, cell_index, exec_reply)
  File "/opt/hostedtoolcache/Python/3.8.18/x64/lib/python3.8/site-packages/nbclient/client.py", line 914, in _check_raise_for_error
    raise CellExecutionError.from_cell_and_msg(cell, exec_reply_content)
nbclient.exceptions.CellExecutionError: An error occurred while executing the following cell:
------------------
import tensorcircuit as tc
import optax
import jax.numpy as jnp
import jax
import tensorflow as tf
import matplotlib.pyplot as plt
from tqdm.notebook import tqdm

import os
os.environ["CUDA_DEVICE_ORDER"]="PCI_BUS_ID"
os.environ["CUDA_VISIBLE_DEVICES"]="1"
os.environ["XLA_PYTHON_CLIENT_PREALLOCATE"]="false"
os.environ["TF_FORCE_GPU_ALLOW_GROWTH"]="true"

plt.rcParams["font.family"] = "serif"
plt.rcParams['mathtext.fontset'] = 'cm'
plt.rcParams['mathtext.rm'] = 'serif'
plt.rc('font', size=14)

key = jax.random.PRNGKey(42)
tf.random.set_seed(42)
------------------


[0;31m---------------------------------------------------------------------------[0m
[0;31mModuleNotFoundError[0m                       Traceback (most recent call last)
Cell [0;32mIn[1], line 1[0m
[0;32m----> 1[0m [38;5;28;01mimport[39;00m [38;5;21;01mtensorcircuit[39;00m [38;5;28;01mas[39;00m [38;5;21;01mtc[39;00m
[1;32m      2[0m [38;5;28;01mimport[39;00m [38;5;21;01moptax[39;00m
[1;32m      3[0m [38;5;28;01mimport[39;00m [38;5;21;01mjax[39;00m[38;5;21;01m.[39;00m[38;5;21;01mnumpy[39;00m [38;5;28;01mas[39;00m [38;5;21;01mjnp[39;00m

[0;31mModuleNotFoundError[0m: No module named 'tensorcircuit'

